Traceback (most recent call last):
  File "/usr/share/miniconda/envs/swd6_hpp/lib/python3.9/site-packages/jupyter_cache/executors/utils.py", line 51, in single_nb_execution
    executenb(
  File "/usr/share/miniconda/envs/swd6_hpp/lib/python3.9/site-packages/nbclient/client.py", line 1093, in execute
    return NotebookClient(nb=nb, resources=resources, km=km, **kwargs).execute()
  File "/usr/share/miniconda/envs/swd6_hpp/lib/python3.9/site-packages/nbclient/util.py", line 84, in wrapped
    return just_run(coro(*args, **kwargs))
  File "/usr/share/miniconda/envs/swd6_hpp/lib/python3.9/site-packages/nbclient/util.py", line 62, in just_run
    return loop.run_until_complete(coro)
  File "/usr/share/miniconda/envs/swd6_hpp/lib/python3.9/asyncio/base_events.py", line 642, in run_until_complete
    return future.result()
  File "/usr/share/miniconda/envs/swd6_hpp/lib/python3.9/site-packages/nbclient/client.py", line 559, in async_execute
    await self.async_execute_cell(
  File "/usr/share/miniconda/envs/swd6_hpp/lib/python3.9/site-packages/nbclient/client.py", line 854, in async_execute_cell
    self._check_raise_for_error(cell, exec_reply)
  File "/usr/share/miniconda/envs/swd6_hpp/lib/python3.9/site-packages/nbclient/client.py", line 756, in _check_raise_for_error
    raise CellExecutionError.from_cell_and_msg(cell, exec_reply_content)
nbclient.exceptions.CellExecutionError: An error occurred while executing the following cell:
------------------
random_array_reconstructed.visualize()
------------------

[0;31m---------------------------------------------------------------------------[0m
[0;31mModuleNotFoundError[0m                       Traceback (most recent call last)
[0;32m/usr/share/miniconda/envs/swd6_hpp/lib/python3.9/site-packages/dask/utils.py[0m in [0;36mimport_required[0;34m(mod_name, error_msg)[0m
[1;32m    168[0m     [0;32mtry[0m[0;34m:[0m[0;34m[0m[0;34m[0m[0m
[0;32m--> 169[0;31m         [0;32mreturn[0m [0mimport_module[0m[0;34m([0m[0mmod_name[0m[0;34m)[0m[0;34m[0m[0;34m[0m[0m
[0m[1;32m    170[0m     [0;32mexcept[0m [0mImportError[0m [0;32mas[0m [0me[0m[0;34m:[0m[0;34m[0m[0;34m[0m[0m

[0;32m/usr/share/miniconda/envs/swd6_hpp/lib/python3.9/importlib/__init__.py[0m in [0;36mimport_module[0;34m(name, package)[0m
[1;32m    126[0m             [0mlevel[0m [0;34m+=[0m [0;36m1[0m[0;34m[0m[0;34m[0m[0m
[0;32m--> 127[0;31m     [0;32mreturn[0m [0m_bootstrap[0m[0;34m.[0m[0m_gcd_import[0m[0;34m([0m[0mname[0m[0;34m[[0m[0mlevel[0m[0;34m:[0m[0;34m][0m[0;34m,[0m [0mpackage[0m[0;34m,[0m [0mlevel[0m[0;34m)[0m[0;34m[0m[0;34m[0m[0m
[0m[1;32m    128[0m [0;34m[0m[0m

[0;32m/usr/share/miniconda/envs/swd6_hpp/lib/python3.9/importlib/_bootstrap.py[0m in [0;36m_gcd_import[0;34m(name, package, level)[0m

[0;32m/usr/share/miniconda/envs/swd6_hpp/lib/python3.9/importlib/_bootstrap.py[0m in [0;36m_find_and_load[0;34m(name, import_)[0m

[0;32m/usr/share/miniconda/envs/swd6_hpp/lib/python3.9/importlib/_bootstrap.py[0m in [0;36m_find_and_load_unlocked[0;34m(name, import_)[0m

[0;31mModuleNotFoundError[0m: No module named 'graphviz'

The above exception was the direct cause of the following exception:

[0;31mRuntimeError[0m                              Traceback (most recent call last)
[0;32m/tmp/ipykernel_4103/3756299828.py[0m in [0;36m<module>[0;34m[0m
[0;32m----> 1[0;31m [0mrandom_array_reconstructed[0m[0;34m.[0m[0mvisualize[0m[0;34m([0m[0;34m)[0m[0;34m[0m[0;34m[0m[0m
[0m
[0;32m/usr/share/miniconda/envs/swd6_hpp/lib/python3.9/site-packages/dask/base.py[0m in [0;36mvisualize[0;34m(self, filename, format, optimize_graph, **kwargs)[0m
[1;32m    212[0m         [0mhttps[0m[0;34m:[0m[0;34m//[0m[0mdocs[0m[0;34m.[0m[0mdask[0m[0;34m.[0m[0morg[0m[0;34m/[0m[0men[0m[0;34m/[0m[0mlatest[0m[0;34m/[0m[0moptimize[0m[0;34m.[0m[0mhtml[0m[0;34m[0m[0;34m[0m[0m
[1;32m    213[0m         """
[0;32m--> 214[0;31m         return visualize(
[0m[1;32m    215[0m             [0mself[0m[0;34m,[0m[0;34m[0m[0;34m[0m[0m
[1;32m    216[0m             [0mfilename[0m[0;34m=[0m[0mfilename[0m[0;34m,[0m[0;34m[0m[0;34m[0m[0m

[0;32m/usr/share/miniconda/envs/swd6_hpp/lib/python3.9/site-packages/dask/base.py[0m in [0;36mvisualize[0;34m(*args, **kwargs)[0m
[1;32m    637[0m     [0mhttps[0m[0;34m:[0m[0;34m//[0m[0mdocs[0m[0;34m.[0m[0mdask[0m[0;34m.[0m[0morg[0m[0;34m/[0m[0men[0m[0;34m/[0m[0mlatest[0m[0;34m/[0m[0moptimize[0m[0;34m.[0m[0mhtml[0m[0;34m[0m[0;34m[0m[0m
[1;32m    638[0m     """
[0;32m--> 639[0;31m     [0;32mfrom[0m [0mdask[0m[0;34m.[0m[0mdot[0m [0;32mimport[0m [0mdot_graph[0m[0;34m[0m[0;34m[0m[0m
[0m[1;32m    640[0m [0;34m[0m[0m
[1;32m    641[0m     [0mfilename[0m [0;34m=[0m [0mkwargs[0m[0;34m.[0m[0mpop[0m[0;34m([0m[0;34m"filename"[0m[0;34m,[0m [0;34m"mydask"[0m[0;34m)[0m[0;34m[0m[0;34m[0m[0m

[0;32m/usr/share/miniconda/envs/swd6_hpp/lib/python3.9/site-packages/dask/dot.py[0m in [0;36m<module>[0;34m[0m
[1;32m      6[0m [0;32mfrom[0m [0;34m.[0m[0mutils[0m [0;32mimport[0m [0mapply[0m[0;34m,[0m [0mfuncname[0m[0;34m,[0m [0mimport_required[0m[0;34m,[0m [0mkey_split[0m[0;34m[0m[0;34m[0m[0m
[1;32m      7[0m [0;34m[0m[0m
[0;32m----> 8[0;31m graphviz = import_required(
[0m[1;32m      9[0m     [0;34m"graphviz"[0m[0;34m,[0m[0;34m[0m[0;34m[0m[0m
[1;32m     10[0m     [0;34m"Drawing dask graphs requires the "[0m[0;34m[0m[0;34m[0m[0m

[0;32m/usr/share/miniconda/envs/swd6_hpp/lib/python3.9/site-packages/dask/utils.py[0m in [0;36mimport_required[0;34m(mod_name, error_msg)[0m
[1;32m    169[0m         [0;32mreturn[0m [0mimport_module[0m[0;34m([0m[0mmod_name[0m[0;34m)[0m[0;34m[0m[0;34m[0m[0m
[1;32m    170[0m     [0;32mexcept[0m [0mImportError[0m [0;32mas[0m [0me[0m[0;34m:[0m[0;34m[0m[0;34m[0m[0m
[0;32m--> 171[0;31m         [0;32mraise[0m [0mRuntimeError[0m[0;34m([0m[0merror_msg[0m[0;34m)[0m [0;32mfrom[0m [0me[0m[0;34m[0m[0;34m[0m[0m
[0m[1;32m    172[0m [0;34m[0m[0m
[1;32m    173[0m [0;34m[0m[0m

[0;31mRuntimeError[0m: Drawing dask graphs requires the `graphviz` python library and the `graphviz` system library to be installed.
RuntimeError: Drawing dask graphs requires the `graphviz` python library and the `graphviz` system library to be installed.

