Traceback (most recent call last):
  File "/opt/hostedtoolcache/Python/3.8.12/x64/lib/python3.8/site-packages/jupyter_cache/executors/utils.py", line 51, in single_nb_execution
    executenb(
  File "/opt/hostedtoolcache/Python/3.8.12/x64/lib/python3.8/site-packages/nbclient/client.py", line 1093, in execute
    return NotebookClient(nb=nb, resources=resources, km=km, **kwargs).execute()
  File "/opt/hostedtoolcache/Python/3.8.12/x64/lib/python3.8/site-packages/nbclient/util.py", line 84, in wrapped
    return just_run(coro(*args, **kwargs))
  File "/opt/hostedtoolcache/Python/3.8.12/x64/lib/python3.8/site-packages/nbclient/util.py", line 62, in just_run
    return loop.run_until_complete(coro)
  File "/opt/hostedtoolcache/Python/3.8.12/x64/lib/python3.8/asyncio/base_events.py", line 616, in run_until_complete
    return future.result()
  File "/opt/hostedtoolcache/Python/3.8.12/x64/lib/python3.8/site-packages/nbclient/client.py", line 559, in async_execute
    await self.async_execute_cell(
  File "/opt/hostedtoolcache/Python/3.8.12/x64/lib/python3.8/site-packages/nbclient/client.py", line 854, in async_execute_cell
    self._check_raise_for_error(cell, exec_reply)
  File "/opt/hostedtoolcache/Python/3.8.12/x64/lib/python3.8/site-packages/nbclient/client.py", line 756, in _check_raise_for_error
    raise CellExecutionError.from_cell_and_msg(cell, exec_reply_content)
nbclient.exceptions.CellExecutionError: An error occurred while executing the following cell:
------------------
ds = xr.tutorial.open_dataset(
    'air_temperature',
    chunks={'time': 'auto'} # dask chunks
)
------------------

[0;31m---------------------------------------------------------------------------[0m
[0;31mModuleNotFoundError[0m                       Traceback (most recent call last)
[0;32m/opt/hostedtoolcache/Python/3.8.12/x64/lib/python3.8/site-packages/xarray/tutorial.py[0m in [0;36mopen_dataset[0;34m(name, cache, cache_dir, engine, **kws)[0m
[1;32m    113[0m     [0;32mtry[0m[0;34m:[0m[0;34m[0m[0;34m[0m[0m
[0;32m--> 114[0;31m         [0;32mimport[0m [0mpooch[0m[0;34m[0m[0;34m[0m[0m
[0m[1;32m    115[0m     [0;32mexcept[0m [0mImportError[0m [0;32mas[0m [0me[0m[0;34m:[0m[0;34m[0m[0;34m[0m[0m

[0;31mModuleNotFoundError[0m: No module named 'pooch'

The above exception was the direct cause of the following exception:

[0;31mImportError[0m                               Traceback (most recent call last)
[0;32m/tmp/ipykernel_1913/286459396.py[0m in [0;36m<module>[0;34m[0m
[0;32m----> 1[0;31m ds = xr.tutorial.open_dataset(
[0m[1;32m      2[0m     [0;34m'air_temperature'[0m[0;34m,[0m[0;34m[0m[0;34m[0m[0m
[1;32m      3[0m     [0mchunks[0m[0;34m=[0m[0;34m{[0m[0;34m'time'[0m[0;34m:[0m [0;34m'auto'[0m[0;34m}[0m [0;31m# dask chunks[0m[0;34m[0m[0;34m[0m[0m
[1;32m      4[0m )

[0;32m/opt/hostedtoolcache/Python/3.8.12/x64/lib/python3.8/site-packages/xarray/tutorial.py[0m in [0;36mopen_dataset[0;34m(name, cache, cache_dir, engine, **kws)[0m
[1;32m    114[0m         [0;32mimport[0m [0mpooch[0m[0;34m[0m[0;34m[0m[0m
[1;32m    115[0m     [0;32mexcept[0m [0mImportError[0m [0;32mas[0m [0me[0m[0;34m:[0m[0;34m[0m[0;34m[0m[0m
[0;32m--> 116[0;31m         raise ImportError(
[0m[1;32m    117[0m             [0;34m"tutorial.open_dataset depends on pooch to download and manage datasets."[0m[0;34m[0m[0;34m[0m[0m
[1;32m    118[0m             [0;34m" To proceed please install pooch."[0m[0;34m[0m[0;34m[0m[0m

[0;31mImportError[0m: tutorial.open_dataset depends on pooch to download and manage datasets. To proceed please install pooch.
ImportError: tutorial.open_dataset depends on pooch to download and manage datasets. To proceed please install pooch.

