Traceback (most recent call last):
  File "/nfs/b0122/Users/earlacoa/miniconda3/envs/swd6_hpp/lib/python3.9/site-packages/jupyter_cache/executors/utils.py", line 51, in single_nb_execution
    executenb(
  File "/nfs/b0122/Users/earlacoa/miniconda3/envs/swd6_hpp/lib/python3.9/site-packages/nbclient/client.py", line 1093, in execute
    return NotebookClient(nb=nb, resources=resources, km=km, **kwargs).execute()
  File "/nfs/b0122/Users/earlacoa/miniconda3/envs/swd6_hpp/lib/python3.9/site-packages/nbclient/util.py", line 84, in wrapped
    return just_run(coro(*args, **kwargs))
  File "/nfs/b0122/Users/earlacoa/miniconda3/envs/swd6_hpp/lib/python3.9/site-packages/nbclient/util.py", line 62, in just_run
    return loop.run_until_complete(coro)
  File "/nfs/b0122/Users/earlacoa/miniconda3/envs/swd6_hpp/lib/python3.9/asyncio/base_events.py", line 642, in run_until_complete
    return future.result()
  File "/nfs/b0122/Users/earlacoa/miniconda3/envs/swd6_hpp/lib/python3.9/site-packages/nbclient/client.py", line 559, in async_execute
    await self.async_execute_cell(
  File "/nfs/b0122/Users/earlacoa/miniconda3/envs/swd6_hpp/lib/python3.9/site-packages/nbclient/client.py", line 854, in async_execute_cell
    self._check_raise_for_error(cell, exec_reply)
  File "/nfs/b0122/Users/earlacoa/miniconda3/envs/swd6_hpp/lib/python3.9/site-packages/nbclient/client.py", line 756, in _check_raise_for_error
    raise CellExecutionError.from_cell_and_msg(cell, exec_reply_content)
nbclient.exceptions.CellExecutionError: An error occurred while executing the following cell:
------------------
client.close()
------------------

[0;31m---------------------------------------------------------------------------[0m
[0;31mNameError[0m                                 Traceback (most recent call last)
[0;32m/tmp/ipykernel_135845/1700138376.py[0m in [0;36m<module>[0;34m[0m
[0;32m----> 1[0;31m [0mclient[0m[0;34m.[0m[0mclose[0m[0;34m([0m[0;34m)[0m[0;34m[0m[0;34m[0m[0m
[0m
[0;31mNameError[0m: name 'client' is not defined
NameError: name 'client' is not defined

